<mujoco model="niryo_one">
  <compiler angle="radian"/>
  <option timestep="0.005" gravity="0 0 0"/>
  <asset>
    <mesh name="base_link" file="base_link.stl"/>
    <mesh name="shoulder_link" file="shoulder_link.stl"/>
    <mesh name="arm_link" file="arm_link.stl"/>
    <mesh name="elbow_link" file="elbow_link.stl"/>
    <mesh name="forearm_link" file="forearm_link.stl"/>
    <mesh name="wrist_link" file="wrist_link.stl"/>
    <mesh name="hand_link" file="hand_link.stl"/>
    <mesh name="g1_mainSupport" file="g1_mainSupport.stl"/>
    <mesh name="g1_clampLeft" file="g1_clampLeft.stl"/>
    <mesh name="g1_clampRight" file="g1_clampRight.stl"/>
    <mesh name="g1_rod" file="g1_rod.stl"/>
    <mesh name="g1_servoHead" file="g1_servoHead.stl"/>
    <!-- <mesh name="waterbottle" file="waterbottle.stl"/> -->
  </asset>
  <worldbody>
    <geom size="0.4 0.4 0.05" pos="0 0 0.05" type="box"/>
    <geom pos="0 0 0.1" type="mesh" mesh="base_link"/>
    <!-- <geom pos="0.3 0.3 0.3" pos="0 0 0.1" mesh="box_small"/> -->
    <!-- <geom pos="0.2 0.1 0.2" type="mesh" mesh="waterbottle"/> -->

    <!-- Light source to illuminate the robot -->
    <!-- <light name="overhead_light" dir="0 0 -1" diffuse="1 1 1" specular="0.5 0.5 0.5" pos="0 0 2"/> -->

    <!-- Robot arm assembly -->
    <body name="shoulder_link" pos="0 0 0.203">
      <inertial pos="0 0 0" mass="0.71142" diaginertia="0.0017 0.0017 0.0032"/>
      <joint name="joint_1" axis="0 0 1" range="-2.949 2.949" actuatorfrcrange="-2 2"/>
      <geom type="mesh" mesh="shoulder_link"/>
      <body name="arm_link" pos="0 0 0.08" quat="0.5 0.5 -0.5 0.5">
        <inertial pos="0 0 0" mass="1.0838" diaginertia="0.008194 0.0011945 0.007915"/>
        <joint name="joint_2" pos="0 0 0" axis="0 0 1" range="-1.83 0.61" actuatorfrcrange="-2.5 2.5"/>
        <geom type="mesh" mesh="arm_link"/>
        <body name="elbow_link" pos="0.21 0 0" quat="0.707107 0 0 -0.707107">
          <inertial pos="0 0 0" mass="0.22126" diaginertia="0.0011754 0.0020851 0.0022753"/>
          <joint name="joint_3" pos="0 0 0" axis="0 0 1" range="-1.34 1.57" actuatorfrcrange="-1 1"/>
          <geom type="mesh" mesh="elbow_link"/>
          <body name="forearm_link" pos="0.0415 0.03 0" quat="0.707107 0 0.707107 0">
            <inertial pos="0 0 0" mass="0.35686" diaginertia="0.0013664 0.0014781 0.00023715"/>
            <joint name="joint_4" pos="0 0 0" axis="0 0 1" range="-2.089 2.089" actuatorfrcrange="-1 1"/>
            <geom type="mesh" mesh="forearm_link"/>
            <body name="wrist_link" pos="0 0 0.20" quat="0.707107 0 -0.707107 0">
              <inertial pos="0 0 0" mass="0.22126" diaginertia="0.0015 0.0015 0.0015"/>
              <joint name="joint_5" pos="0 0 0" axis="0 0 1" range="-1.74533 1.91986" actuatorfrcrange="-1 1"/>
              <geom type="mesh" mesh="wrist_link"/>
              <body name="hand_link" pos="0.0164 -0.0055 0" quat="0.707107 0 0.707107 0">
                <inertial pos="0 0 0" mass="0.0070027" diaginertia="0.0015 0.0015 0.0015"/>
                <joint name="joint_6" pos="0 0 0" axis="0 0 1" range="-2.57436 2.57436" actuatorfrcrange="-0.5 0.5"/>
                <geom type="mesh" mesh="hand_link"/>
                <!-- <body name="tool_link" pos="0 0 0.0073" quat="0.707 0 0 -0.707"> -->
                  <!-- Gripper Assembly -->
                <body name="g1_mainSupport" pos="0.027 0 0.015" quat="0 0.707 -0.707 0">
                  <geom type="mesh" mesh="g1_mainSupport"/>
                  <joint name="g1_servo_joint" type="hinge" axis="0 0 1" range="-1.5708 1.5708" damping="0.1" stiffness="0.1"/>
                  <body name="g1_clamp_left" pos="0 0 0">
                    <!-- <geom type="mesh" mesh="g1_rod"/> -->
                    <joint name="left_clamp_joint" type="slide" axis="1 0 0" range="-0.012 0" actuatorfrcrange="-0.5 0.5"/>
                    <geom type="mesh" mesh="g1_clampLeft"/>
                  </body>
                  <body name="g1_clamp_right" pos="0 0 0">
                    <!-- <geom type="mesh" mesh="g1_rod"/> -->
                    <joint name="right_clamp_joint" type="slide" axis="1 0 0" range="0 0.012" actuatorfrcrange="-0.5 0.5"/>
                    <geom type="mesh" mesh="g1_clampRight"/>
                  </body>
                  <!-- </body> -->
                </body>
              </body>
            </body>
          </body>
        </body>
      </body>
    </body>
  </worldbody>
  <actuator>
    <position joint="joint_1"/>
    <position joint="joint_2"/>
    <position joint="joint_3"/>
    <position joint="joint_4"/>
    <position joint="joint_5"/>
    <position joint="joint_6"/>
    <position joint="left_clamp_joint"/>
    <position joint="right_clamp_joint"/>
  </actuator>
</mujoco>
