<?xml version="1.0" ?><robot name="niryo_one">
    <link name="world">
    </link>

    <link name="base_link" quat="0.9961946980917455 0.0 0.0 0.08715574274765817">
        <visual>
            <geometry>
                <mesh filename="arm_link.dae"/>
            </geometry>
        </visual>
        <collision>
            <geometry>
                <mesh filename="base_link.stl"/>
            </geometry>
        </collision>
    </link>

    <link name="shoulder_link" quat="0.984807753012208 -0.0 -0.0 -0.17364817766693033">
        <visual>
            <geometry>
                <mesh filename="shoulder_link.dae"/>
            </geometry>
        </visual>
        <collision>
            <geometry>
                <mesh filename="shoulder_link.stl"/>
            </geometry>
        </collision>
    </link>

    <link name="arm_link" quat="0.9659258262890683 0.0 0.0 0.25881904510252074">
        <visual>
            <geometry>
                <mesh filename="arm_link.dae"/>
            </geometry>
        </visual>
        <collision>
            <geometry>
                <mesh filename="arm_link.stl"/>
            </geometry>
        </collision>
    </link>

    <link name="elbow_link" quat="0.9396926207859084 -0.0 -0.0 -0.3420201433256687">
        <visual>
            <geometry>
                <mesh filename="elbow_link.dae"/>
            </geometry>
        </visual>
        <collision>
            <geometry>
                <mesh filename="elbow_link.stl"/>
            </geometry>
        </collision>
    </link>

    <link name="forearm_link" quat="0.9063077870366499 0.0 0.0 0.42261826174069944">
        <visual>
            <geometry>
                <mesh filename="forearm_link.dae"/>
            </geometry>
        </visual>
        <collision>
            <geometry>
                <mesh filename="forearm_link.stl"/>
            </geometry>
        </collision>
    </link>

    <link name="wrist_link" quat="0.8660254037844387 -0.0 -0.0 -0.49999999999999994">
        <visual>
            <geometry>
                <mesh filename="wrist_link.dae"/>
            </geometry>
        </visual>
        <collision>
            <geometry>
                <mesh filename="wrist_link.stl"/>
            </geometry>
        </collision>
    </link>

    <link name="hand_link">
        <visual>
            <geometry>
                <mesh filename="hand_link.dae"/>
            </geometry>
        </visual>
        <collision>
            <geometry>
                <mesh filename="hand_link.stl"/>
            </geometry>
        </collision>
    </link>

    <link name="tool_link">

    </link>

    <!-- Joints -->
    <joint name="joint_world" type="fixed">
        <parent link="world"/>
        <child link="base_link"/>
        <origin xyz="0 0 0" rpy="0 0 0"/>
    </joint>

    <joint name="joint_1" type="revolute">
        <parent link="base_link"/>
        <child link="shoulder_link"/>
        <origin xyz="0 0 0.103" rpy="0 0 0"/>
        <axis xyz="0 0 1"/>
        <limit effort="1" velocity="1.0" lower="-3.05433" upper="3.05433"/>
    </joint>

    <joint name="joint_2" type="revolute">
        <parent link="shoulder_link"/>
        <child link="arm_link"/>
        <origin xyz="0 0 0.08" rpy="1.57079632679 -1.57079632679 0"/>
        <axis xyz="0 0 1"/>
        <limit effort="1" velocity="1.0" lower="-1.57080" upper="0.640187"/>
    </joint>

    <joint name="joint_3" type="revolute">
        <parent link="arm_link"/>
        <child link="elbow_link"/>
        <origin xyz="0.21 0.0 0" rpy="0 0 -1.57079632679"/>
        <axis xyz="0 0 1"/>
        <limit effort="1" velocity="1.0" lower="-1.397485" upper="1.57079632679"/>
    </joint>

    <joint name="joint_4" type="revolute">
        <parent link="elbow_link"/>
        <child link="forearm_link"/>
        <origin xyz="0.0415 0.03 0" rpy="0 1.57079632679 0"/>
        <axis xyz="0 0 1"/>
        <limit effort="1" velocity="1.0" lower="-3.05433" upper="3.05433"/>
    </joint>

    <joint name="joint_5" type="revolute">
        <parent link="forearm_link"/>
        <child link="wrist_link"/>
        <origin xyz="0 0 0.18" rpy="0 -1.57079632679 0"/>
        <axis xyz="0 0 1"/>
        <limit effort="1" velocity="1.0" lower="-1.74533" upper="1.91986"/>
    </joint>

    <joint name="joint_6" type="revolute">
        <parent link="wrist_link"/>
        <child link="hand_link"/>
        <origin xyz="0.0164 -0.0055 0" rpy="0 1.57079632679 0"/>
        <axis xyz="0 0 1"/>
        <limit effort="1" velocity="1.0" lower="-2.57436" upper="2.57436"/>
    </joint>

    <joint name="hand_tool_joint" type="fixed">
        <parent link="hand_link"/>
        <child link="tool_link"/>
        <origin xyz="0 0 0.0073" rpy="-1.57079632679 -1.57079632679 0"/>
    </joint>
</robot>