<mujoco model="niryo_one">
  <compiler angle="radian"/>
  <asset>
    <mesh name="base_link" file="base_link.stl"/>
    <mesh name="shoulder_link" file="shoulder_link.stl"/>
    <mesh name="arm_link" file="arm_link.stl"/>
    <mesh name="elbow_link" file="elbow_link.stl"/>
    <mesh name="forearm_link" file="forearm_link.stl"/>
    <mesh name="wrist_link" file="wrist_link.stl"/>
    <mesh name="hand_link" file="hand_link.stl"/>
    <mesh name="g1_mainSupport" file="g1_mainSupport.stl"/>
    <mesh name="g1_clampLeft" file="g1_clampLeft.stl"/>
    <mesh name="g1_clampRight" file="g1_clampRight.stl"/>
    <mesh name="waterbottle" file="waterbottle.stl"/>
  </asset>
  <worldbody>
    <geom size="0.5 0.5 0.05" pos="0 0 0.05" type="box"/>
    <geom pos="0 0 0.1" type="mesh" mesh="base_link"/>
    <geom pos="0.2 0.5 0.15" type="mesh" mesh="waterbottle"/>
    <body name="shoulder_link" pos="0 0 0.203">
      <joint name="joint_1" pos="0 0 0" axis="0 0 1" range="-3.05433 3.05433" actuatorfrcrange="-1 1"/>
      <geom type="mesh" mesh="shoulder_link"/>
      <body name="arm_link" pos="0 0 0.08" quat="0.5 0.5 -0.5 0.5">
        <joint name="joint_2" pos="0 0 0" axis="0 0 1" range="-1.5708 0.640187" actuatorfrcrange="-1 1"/>
        <geom type="mesh" mesh="arm_link"/>
        <body name="elbow_link" pos="0.21 0 0" quat="0.707107 0 0 -0.707107">
          <joint name="joint_3" pos="0 0 0" axis="0 0 1" range="-1.39749 1.5708" actuatorfrcrange="-1 1"/>
          <geom type="mesh" mesh="elbow_link"/>
          <body name="forearm_link" pos="0.0415 0.03 0" quat="0.707107 0 0.707107 0">
            <joint name="joint_4" pos="0 0 0" axis="0 0 1" range="-3.05433 3.05433" actuatorfrcrange="-1 1"/>
            <geom type="mesh" mesh="forearm_link"/>
            <body name="wrist_link" pos="0 0 0.18" quat="0.707107 0 -0.707107 0">
              <joint name="joint_5" pos="0 0 0" axis="0 0 1" range="-1.74533 1.91986" actuatorfrcrange="-1 1"/>
              <geom type="mesh" mesh="wrist_link"/>
              <body name="hand_link" pos="0.0164 -0.0055 0" quat="0.707107 0 0.707107 0">
                <joint name="joint_6" pos="0 0 0" axis="0 0 1" range="-2.57436 2.57436" actuatorfrcrange="-1 1"/>
                <geom type="mesh" mesh="hand_link"/>
                <geom pos="0.027 0 0.015" quat="-0.499999 0.499999 0.500001 -0.500001" type="mesh" mesh="g1_mainSupport"/>
                <body name="gripper_clamp_left" pos="0.027 0 0.015" quat="-0.499999 0.499999 0.500001 -0.500001">
                  <joint name="left_clamp_joint" pos="0 0 0" axis="1 0 0" type="slide" range="-0.012 0" actuatorfrcrange="-1 1"/>
                  <geom type="mesh" mesh="g1_clampLeft"/>
                </body>
                <body name="gripper_clamp_right" pos="0.027 0 0.015" quat="-0.499999 0.499999 0.500001 -0.500001">
                  <joint name="right_clamp_joint" pos="0 0 0" axis="1 0 0" type="slide" range="0 0.012" actuatorfrcrange="-1 1"/>
                  <geom type="mesh" mesh="g1_clampRight"/>
                </body>
              </body>
            </body>
          </body>
        </body>
      </body>
    </body>
  </worldbody>
</mujoco>
