<mujoco model="niryo_one">
  <compiler angle="radian"/>
  <option timestep="0.005" gravity="0 0 -9.8"/>
  <asset>
    <mesh name="base_link" file="base_link.stl"/>
    <mesh name="shoulder_link" file="shoulder_link.stl"/>
    <mesh name="arm_link" file="arm_link.stl"/>
    <mesh name="elbow_link" file="elbow_link.stl"/>
    <mesh name="forearm_link" file="forearm_link.stl"/>
    <mesh name="wrist_link" file="wrist_link.stl"/>
    <mesh name="hand_link" file="hand_link.stl"/>
    <mesh name="g1_mainSupport" file="g1_mainSupport.stl"/>
    <mesh name="g1_clampLeft" file="g1_clampLeft.stl"/>
    <mesh name="g1_clampRight" file="g1_clampRight.stl"/>
  </asset>
  <worldbody>
    <geom pos="0 0 0.1" type="mesh" mesh="base_link"/>
    <light name="overhead_light" pos="0 0 2" dir="0 0 -1" diffuse="1 1 1" specular="0.5 0.5 0.5"/>
    <body name="table">
      <geom name="table_top" size="1.0 1.0 0.05" pos="0 0 0.05" type="box" rgba="0.8 0.8 0.8 1"/>
    </body>
    <body name="shoulder_link" pos="0 0 0.203">
      <inertial pos="0 0 0" mass="0.71142" diaginertia="0.0017 0.0017 0.0032"/>
      <joint name="joint_1" pos="0 0 0" axis="0 0 1" range="-2.949 2.949" actuatorfrcrange="-2 2"/>
      <geom type="mesh" mesh="shoulder_link"/>
      <body name="arm_link" pos="0 0 0.08" quat="0.5 0.5 -0.5 0.5">
        <inertial pos="0 0 0" mass="1.0838" diaginertia="0.008194 0.0011945 0.007915"/>
        <joint name="joint_2" pos="0 0 0" axis="0 0 1" range="-1.83 0.61" actuatorfrcrange="-2.5 2.5"/>
        <geom type="mesh" mesh="arm_link"/>
        <body name="elbow_link" pos="0.21 0 0" quat="0.707107 0 0 -0.707107">
          <inertial pos="0 0 0" mass="0.22126" diaginertia="0.0011754 0.0020851 0.0022753"/>
          <joint name="joint_3" pos="0 0 0" axis="0 0 1" range="-1.34 1.57" actuatorfrcrange="-1 1"/>
          <geom type="mesh" mesh="elbow_link"/>
          <body name="forearm_link" pos="0.0415 0.03 0" quat="0.707107 0 0.707107 0">
            <inertial pos="0 0 0" mass="0.35686" diaginertia="0.0013664 0.0014781 0.00023715"/>
            <joint name="joint_4" pos="0 0 0" axis="0 0 1" range="-2.089 2.089" actuatorfrcrange="-2 2"/>
            <geom type="mesh" mesh="forearm_link"/>
            <body name="wrist_link" pos="0 0 0.19" quat="0.707107 0 -0.707107 0">
              <inertial pos="0 0 0" mass="0.22126" diaginertia="0.0015 0.0015 0.0015"/>
              <joint name="joint_5" pos="0 0 0" axis="0 0 1" range="-1.04533 0.2397" actuatorfrcrange="-1 1"/>
              <geom type="mesh" mesh="wrist_link"/>
              <body name="hand_link" pos="0.0164 0 0" quat="0.707107 0 0.707107 0">
                <inertial pos="0 0 0" mass="0.0070027" diaginertia="0.0015 0.0015 0.0015"/>
                <joint name="joint_6" pos="0 0 0" axis="0 0 1" range="-1.57436 1.57436" actuatorfrcrange="-1 1"/>
                <geom type="mesh" mesh="hand_link"/>
                <body name="g1_mainSupport_link" pos="0 0 0.0203" quat="0 1 0 0">
                  <inertial pos="0 0 0" mass="0.04" diaginertia="3.9e-05 3.9e-05 6.7e-05"/>
                  <geom type="mesh" mesh="g1_mainSupport"/>
                  <site name="gripper_center" pos="0 0 -0.0453" size="0.01" rgba="0 0 0 1"/>
                  <body name="gripper_clamp_left" quat="0 0 0 1">
                    <joint name="left_clamp_joint" pos="0 0 0" axis="1 0 0" type="slide" range="-0.012 0" actuatorfrcrange="-1 1"/>
                    <geom type="mesh" mesh="g1_clampLeft"/>
                  </body>
                  <body name="gripper_clamp_right" quat="0 0 0 1">
                    <joint name="right_clamp_joint" pos="0 0 0" axis="1 0 0" type="slide" range="0 0.012" actuatorfrcrange="-1 1"/>
                    <geom type="mesh" mesh="g1_clampRight"/>
                  </body>
                </body>
              </body>
            </body>
          </body>
        </body>
      </body>
    </body>
    <body name="ball" pos="0.10 -0.10 0.15">
      <joint name="ball_x" type="slide" pos="0 0 0" axis="1 0 0" range="-10 10"/>
      <joint name="ball_y" type="slide" pos="0 0 0" axis="0 1 0" range="-10 10"/>
      <joint name="ball_z" type="slide" pos="0 0 0" axis="0 0 1" range="-10 10"/>
      <geom name="ball" size="0.01" rgba="0.65 0.81 0.55 1"/>
    </body>
  </worldbody>
  <actuator>
    <general joint="joint_1" biastype="affine" biasprm="0 -1" name="joint_1"/>
    <general joint="joint_2" biastype="affine" biasprm="0 -1" name="joint_2"/>
    <general joint="joint_3" biastype="affine" biasprm="0 -1" name="joint_3"/>
    <general joint="joint_4" biastype="affine" biasprm="0 -1" name="joint_4"/>
    <general joint="joint_5" biastype="affine" biasprm="0 -1" name="joint_5"/>
    <general joint="joint_6" biastype="affine" biasprm="0 -1" name="joint_6"/>
    <general joint="left_clamp_joint" biastype="affine" biasprm="0 -1" name="left_clamp_joint"/>
    <general joint="right_clamp_joint" biastype="affine" biasprm="0 -1" name="right_clamp_joint"/>
    <position joint="ball_x" kp="1000" name="ball_x"/>
    <position joint="ball_y" kp="1000" name="ball_y"/>
    <position joint="ball_z" kp="1000" name="ball_z"/>
  </actuator>
  <sensor>
    <touch site="gripper_center" name="touch"/>
  </sensor>
</mujoco>
