<?xml version="1.0" ?>
<!-- =================================================================================== -->
<!-- |    This document was autogenerated by xacro from niryo_one.urdf.xacro           | -->
<!-- |    EDITING THIS FILE BY HAND IS NOT RECOMMENDED                                 | -->
<!-- =================================================================================== -->
<!--
    niryo_one.urdf.xacro
    Copyright (C) 2017 Niryo
    All rights reserved.

    This program is free software: you can redistribute it and/or modify
    it under the terms of the GNU General Public License as published by
    the Free Software Foundation, either version 3 of the License, or
    (at your option) any later version.

    This program is distributed in the hope that it will be useful,
    but WITHOUT ANY WARRANTY; without even the implied warranty of
    MERCHANTABILITY or FITNESS FOR A PARTICULAR PURPOSE.  See the
    GNU General Public License for more details.

    You should have received a copy of the GNU General Public License
    along with this program.  If not, see <http://www.gnu.org/licenses/>.
-->
<robot name="niryo_one" xmlns:xacro="http://www.ros.org/wiki/xacro">
  <!-- Properties -->
  <!-- Links -->
  <link name="world"/>

  <link name="base_link">
    <visual>
      <origin rpy="0 0 0" xyz="0 0 0"/>
      <geometry>
        <mesh filename="package://niryo_one_description/meshes/v2/collada/base_link.dae"/>
      </geometry>
    </visual>
    <collision>
      <origin rpy="0 0 0" xyz="0 0 0"/>
      <geometry>
        <mesh filename="package://niryo_one_description/meshes/v2/stl/base_link.stl"/>
      </geometry>
    </collision>
  </link>

  <link name="shoulder_link">
    <visual>
      <origin rpy="0 0 0" xyz="0 0 0"/>
      <geometry>
        <mesh filename="package://niryo_one_description/meshes/v2/collada/shoulder_link.dae"/>
      </geometry>
    </visual>
    <collision>
      <origin rpy="0 0 0" xyz="0 0 0"/>
      <geometry>
        <mesh filename="package://niryo_one_description/meshes/v2/stl/shoulder_link.stl"/>
      </geometry>
    </collision>
  </link>

  <link name="arm_link">
    <visual>
      <origin rpy="0 0 0" xyz="0 0 0"/>
      <geometry>
        <mesh filename="package://niryo_one_description/meshes/v2/collada/arm_link.dae"/>
      </geometry>
    </visual>
    <collision>
      <origin rpy="0 0 0" xyz="0 0 0"/>
      <geometry>
        <mesh filename="package://niryo_one_description/meshes/v2/stl/arm_link.stl"/>
      </geometry>
    </collision>
  </link>

  <link name="elbow_link">
    <visual>
      <origin rpy="0 0 0" xyz="0 0 0"/>
      <geometry>
        <mesh filename="package://niryo_one_description/meshes/v2/collada/elbow_link.dae"/>
      </geometry>
    </visual>
    <collision>
      <origin rpy="0 0 0" xyz="0 0 0"/>
      <geometry>
        <mesh filename="package://niryo_one_description/meshes/v2/stl/elbow_link.stl"/>
      </geometry>
    </collision>
  </link>
  <link name="forearm_link">
    <visual>
      <origin rpy="0 0 0" xyz="0 0 0"/>
      <geometry>
        <mesh filename="package://niryo_one_description/meshes/v2/collada/forearm_link.dae"/>
      </geometry>
    </visual>
    <collision>
      <origin rpy="0 0 0" xyz="0 0 0"/>
      <geometry>
        <mesh filename="package://niryo_one_description/meshes/v2/stl/forearm_link.stl"/>
      </geometry>
    </collision>
  </link>
  <link name="wrist_link">
    <visual>
      <origin rpy="0 0 0" xyz="0 0 0"/>
      <geometry>
        <mesh filename="package://niryo_one_description/meshes/v2/collada/wrist_link.dae"/>
      </geometry>
    </visual>
    <collision>
      <origin rpy="0 0 0" xyz="0 0 0"/>
      <geometry>
        <mesh filename="package://niryo_one_description/meshes/v2/stl/wrist_link.stl"/>
      </geometry>
    </collision>
  </link>
  <link name="hand_link">
    <visual>
      <origin rpy="0 0 0" xyz="0 0 0"/>
      <geometry>
        <mesh filename="package://niryo_one_description/meshes/v2/collada/hand_link.dae"/>
      </geometry>
    </visual>
    <collision>
      <origin rpy="0 0 0" xyz="0 0 0"/>
      <geometry>
        <mesh filename="package://niryo_one_description/meshes/v2/stl/hand_link.stl"/>
      </geometry>
    </collision>
  </link>

  <link name="g1_main_support">
      <visual>
        <origin xyz="0 0 0 " rpy="0 0 0" />
        <geometry>
          <mesh filename="package://niryo_one_tools_support/meshes/gripper_1/collada/g1_mainSupport.dae" />
        </geometry>
      </visual>
      <collision>
        <origin xyz="0 0 0 " rpy="0 0 0" />
        <geometry>
          <mesh filename="package://niryo_one_tools_support/meshes/gripper_1/stl/g1_mainSupport.stl" />
        </geometry>
      </collision>
      <inertial>
        <origin xyz="0 0 0" rpy="0 0 0" />
        <mass value="0.04" />
        <!-- <inertia ixx="0.000015" ixy="0.0" ixz="0.0" iyy="0.00000975" iyz="0.0" izz="0.000001107"/> -->
      </inertial>
    </link>


  
  <!-- Left Clamp of the Gripper -->
  <link name="g1_clamp_left">
    <visual>
      <origin xyz="0 0 0" rpy="0 0 0"/>
      <geometry>
        <mesh filename="package://niryo_one_description/meshes/g1_clampLeft.dae"/>
      </geometry>
    </visual>
    <collision>
      <origin xyz="0 0 0" rpy="0 0 0"/>
      <geometry>
        <mesh filename="package://niryo_one_description/meshes/g1_clampLeft.stl"/>
      </geometry>
    </collision>
    <inertial>
      <origin xyz="0 0 0" rpy="0 0 0" />
      <mass value="0.015" />
      <!-- <inertia ixx="0.0000009" ixy="0.0" ixz="0.0" iyy="0.0000044" iyz="0.0" izz="0.0000041"/> -->
    </inertial>
  </link>

  <!-- Right Clamp of the Gripper -->
  <link name="g1_clamp_right">
    <visual>
      <origin xyz="0 0 0" rpy="0 0 0"/>
      <geometry>
        <mesh filename="package://niryo_one_description/meshes/g1_clampRight.dae"/>
      </geometry>
    </visual>
    <collision>
      <origin xyz="0 0 0" rpy="0 0 0"/>
      <geometry>
        <mesh filename="package://niryo_one_description/meshes/g1_clampRight.stl"/>
      </geometry>
    </collision>
    <inertial>
      <origin xyz="0 0 0" rpy="0 0 0" />
      <mass value="0.015" />
      <!-- <inertia ixx="0.0000009" ixy="0.0" ixz="0.0" iyy="0.0000044" iyz="0.0" izz="0.0000041"/> -->
    </inertial>
  </link>

  <!--Joints -->
  <joint name="joint_1" type="revolute">
    <parent link="base_link"/>
    <child link="shoulder_link"/>
    <origin rpy="0 0 0" xyz="0 0 0.203"/>
    <axis xyz="0 0 1"/>
    <limit effort="1" lower="-2.49433" upper="2.49433" velocity="1.0"/>
  </joint>
  <joint name="joint_2" type="revolute">
    <parent link="shoulder_link"/>
    <child link="arm_link"/>
    <origin rpy="0.61207963268 -1.3007963268 0" xyz="0 0 0.08"/>
    <limit effort="1" lower="-1.5708" upper="0.640187" velocity="1.0"/>
    <axis xyz="0 0 1"/>
  </joint>
  <joint name="joint_3" type="revolute">
    <parent link="arm_link"/>
    <child link="elbow_link"/>
    <origin rpy="0 0 -1.5707963268" xyz="0.21 0.0 0"/>
    <limit effort="1" lower="-1.34 " upper="1.57" velocity="1.0"/>
    <axis xyz="0 0 1"/>
  </joint>
  <joint name="joint_4" type="revolute">
    <parent link="elbow_link"/>
    <child link="forearm_link"/>
    <origin rpy="0 1.5707963268 0" xyz="0.0415 0.03 0"/>
    <limit effort="1" lower="-2.089" upper="2.089" velocity="1.0"/>
    <axis xyz="0 0 1"/>
  </joint>
  <joint name="joint_5" type="revolute">
    <parent link="forearm_link"/>
    <child link="wrist_link"/>
    <origin rpy="0 -1.5707963268 0" xyz="0 0 0.19"/>
    <limit effort="1" lower="-1.74533" upper="1.3000" velocity="1.0"/>
    <axis xyz="0 0 1"/>
  </joint>
  <joint name="joint_6" type="revolute">
    <parent link="wrist_link"/>
    <child link="hand_link"/>
    <!-- rpy pass, xyz the above joint position with a name  -->
    <origin rpy="0 0 1.60005" xyz="0.0164 -0.0055 0"/>
    <limit effort="1" lower="-2.57436" upper="2.57436" velocity="1.0"/>
    <!-- <limit effort="1" lower="1.59990" upper="1.60005" velocity="1.0"/> -->
    <axis xyz="0 0 1"/>
  </joint>

  <joint name="${prefix}niryo_gripper_1_joint" type="fixed">
      <!-- The parent link must be read from the robot model it is attached to. -->
      <parent link="hand_link"/>
      <child link="g1_main_support"/>
      <!-- The tool is directly attached to the flange. - ->
      <origin rpy="0 0 0" xyz="0 0 0"/>-->
      <origin xyz="0.027 0 0.015 " rpy="4.712388980385 0 1.57079632" />
    </joint>

  <!-- Prismatic joint for left clamp -->

  <joint name="left_clamp_joint" type="prismatic">
      <parent link="g1_main_support" />
      <child link="g1_clamp_left" />
      <origin xyz="0.027 0 0.015" rpy="0 0 0" />
      <limit effort="100.0" velocity="3.0" lower="-0.012" upper="0" />
      <axis xyz="1 0 0" />
      <dynamics damping="0.1" friction="0.0" />
    </joint>


  <!-- Prismatic joint for right clamp -->

  <joint name="right_clamp_joint" type="prismatic">
      <parent link="g1_main_support" />
      <child link="g1_clamp_right" />
      <origin xyz="0.027 0 0.015" rpy="0 0 0" />
      <limit effort="100.0" velocity="3.0" lower="0" upper="0.012" />
      <axis xyz="1 0 0" />
      <dynamics damping="0.1" friction="0.0" />
      <!--<mimic joint="${prefix}left_clamp_joint" multiplier="-1" offset="0" />-->
    </joint>

</robot>
