<?xml version="1.0" ?>
<robot name="niryo_one" xmlns:xacro="http://www.ros.org/wiki/xacro">
  <!-- Properties -->
  
  <!-- Links -->
  <link name="base_link">
    <visual>
      <origin xyz="0 0 0.1"/>
      <geometry>
        <mesh filename="package://niryo_one_description/meshes/v2/stl/base_link.stl"/>
      </geometry>
    </visual>
    <collision>
      <origin xyz="0 0 0.1"/>
      <geometry>
        <mesh filename="package://niryo_one_description/meshes/v2/stl/base_link.stl"/>
      </geometry>
    </collision>
  </link>
  
  <link name="shoulder_link">
    <visual>
      <origin xyz="0 0 0.203"/>
      <geometry>
        <mesh filename="package://niryo_one_description/meshes/v2/stl/shoulder_link.stl"/>
      </geometry>
    </visual>
    <collision>
      <origin xyz="0 0 0.203"/>
      <geometry>
        <mesh filename="package://niryo_one_description/meshes/v2/stl/shoulder_link.stl"/>
      </geometry>
    </collision>
  </link>

  <link name="arm_link">
    <visual>
      <origin xyz="0 0 0.08"/>
      <geometry>
        <mesh filename="package://niryo_one_description/meshes/v2/stl/arm_link.stl"/>
      </geometry>
    </visual>
    <collision>
      <origin xyz="0 0 0.08"/>
      <geometry>
        <mesh filename="package://niryo_one_description/meshes/v2/stl/arm_link.stl"/>
      </geometry>
    </collision>
  </link>

  <link name="elbow_link">
    <visual>
      <origin xyz="0.21 0 0"/>
      <geometry>
        <mesh filename="package://niryo_one_description/meshes/v2/stl/elbow_link.stl"/>
      </geometry>
    </visual>
    <collision>
      <origin xyz="0.21 0 0"/>
      <geometry>
        <mesh filename="package://niryo_one_description/meshes/v2/stl/elbow_link.stl"/>
      </geometry>
    </collision>
  </link>

  <link name="forearm_link">
    <visual>
      <origin xyz="0.0415 0.03 0"/>
      <geometry>
        <mesh filename="package://niryo_one_description/meshes/v2/stl/forearm_link.stl"/>
      </geometry>
    </visual>
    <collision>
      <origin xyz="0.0415 0.03 0"/>
      <geometry>
        <mesh filename="package://niryo_one_description/meshes/v2/stl/forearm_link.stl"/>
      </geometry>
    </collision>
  </link>

  <link name="wrist_link">
    <visual>
      <origin xyz="0 0 0.18"/>
      <geometry>
        <mesh filename="package://niryo_one_description/meshes/v2/stl/wrist_link.stl"/>
      </geometry>
    </visual>
    <collision>
      <origin xyz="0 0 0.18"/>
      <geometry>
        <mesh filename="package://niryo_one_description/meshes/v2/stl/wrist_link.stl"/>
      </geometry>
    </collision>
  </link>

  <link name="hand_link">
    <visual>
      <origin xyz="0.0164 -0.0055 0"/>
      <geometry>
        <mesh filename="package://niryo_one_description/meshes/v2/stl/hand_link.stl"/>
      </geometry>
    </visual>
    <collision>
      <origin xyz="0.0164 -0.0055 0"/>
      <geometry>
        <mesh filename="package://niryo_one_description/meshes/v2/stl/hand_link.stl"/>
      </geometry>
    </collision>
  </link>

  <!-- Joints -->
  <joint name="joint_1" type="revolute">
    <parent link="base_link"/>
    <child link="shoulder_link"/>
    <origin xyz="0 0 0.203" rpy="0 0 0"/>
    <axis xyz="0 0 1"/>
    <limit lower="-2.949" upper="2.949" velocity="1.0" effort="1"/>
  </joint>
  
  <joint name="joint_2" type="revolute">
    <parent link="shoulder_link"/>
    <child link="arm_link"/>
    <origin xyz="0 0 0.08" rpy="0.5 -0.5 0"/>
    <axis xyz="0 0 1"/>
    <limit lower="-1.83" upper="0.61" velocity="1.0" effort="1"/>
  </joint>
  
  <joint name="joint_3" type="revolute">
    <parent link="arm_link"/>
    <child link="elbow_link"/>
    <origin xyz="0.21 0 0" rpy="0 0 -1.5708"/>
    <axis xyz="0 0 1"/>
    <limit lower="-1.34" upper="1.57" velocity="1.0" effort="1"/>
  </joint>
  
  <joint name="joint_4" type="revolute">
    <parent link="elbow_link"/>
    <child link="forearm_link"/>
    <origin xyz="0.0415 0.03 0" rpy="0 1.5708 0"/>
    <axis xyz="0 0 1"/>
    <limit lower="-2.089" upper="2.089" velocity="1.0" effort="1"/>
  </joint>
  
  <joint name="joint_5" type="revolute">
    <parent link="forearm_link"/>
    <child link="wrist_link"/>
    <origin xyz="0 0 0.18" rpy="0 -1.5708 0"/>
    <axis xyz="0 0 1"/>
    <limit lower="-1.74533" upper="1.91986" velocity="1.0" effort="1"/>
  </joint>
  
  <joint name="joint_6" type="revolute">
    <parent link="wrist_link"/>
    <child link="hand_link"/>
    <origin xyz="0.0164 -0.0055 0" rpy="0 1.5708 0"/>
    <axis xyz="0 0 1"/>
    <limit lower="-2.57436" upper="2.57436" velocity="1.0" effort="1"/>
  </joint>

  <joint name="hand_tool_joint_1" type="fixed">
    <parent link="hand_link"/>
    <child link="tool_link_1"/>
    <origin xyz="0.027 0 0.015" rpy="-0.5 0.5 0.5"/>
  </joint>
  
  <joint name="hand_tool_joint_2" type="fixed">
    <parent link="hand_link"/>
    <child link="tool_link_2"/>
    <origin xyz="0.027 0 0.015" rpy="-0.5 0.5 0.5"/>
  </joint>
  
</robot>
