<mujoco model="niryo_one">
    <compiler angle="radian"/>
    <option timestep="0.005" gravity="0 0 -9.81"/>
    <asset>
        <mesh name="base_link" file="base_link.stl"/>
        <mesh name="shoulder_link" file="shoulder_link.stl"/>
        <mesh name="arm_link" file="arm_link.stl"/>
        <mesh name="elbow_link" file="elbow_link.stl"/>
        <mesh name="forearm_link" file="forearm_link.stl"/>
        <mesh name="wrist_link" file="wrist_link.stl"/>
        <mesh name="hand_link" file="hand_link.stl"/>
    </asset>
    <worldbody>
        <body name="base_link" pos="0 0 0">
            <geom type="mesh" mesh="base_link"/>
            <body name="shoulder_link" pos="0 0 0.103">
                <geom type="mesh" mesh="shoulder_link"/>
                <joint type="hinge" axis="0 0 1" range="-3.05433 3.05433"/>
                <body name="arm_link" pos="0 0 0.08">
                    <geom type="mesh" mesh="arm_link"/>
                    <joint type="hinge" axis="0 0 1" range="-1.5708 0.640187"/>
                    <body name="elbow_link" pos="0.21 0 0">
                        <geom type="mesh" mesh="elbow_link"/>
                        <joint type="hinge" axis="0 0 1" range="-1.397485 1.5707963268"/>
                        <body name="forearm_link" pos="0.0415 0.03 0">
                            <geom type="mesh" mesh="forearm_link"/>
                            <joint type="hinge" axis="0 0 1" range="-3.05433 3.05433"/>
                            <body name="wrist_link" pos="0 0 0.18">
                                <geom type="mesh" mesh="wrist_link"/>
                                <joint type="hinge" axis="0 0 1" range="-1.74533 1.91986"/>
                                <body name="hand_link" pos="0.0164 -0.0055 0">
                                    <geom type="mesh" mesh="hand_link"/>
                                    <joint type="hinge" axis="0 0 1" range="-2.57436 2.57436"/>
                                    <body name="tool_link" pos="0 0 0.0073">
                                        <!-- Tool link details if necessary -->
                                    </body>
                                </body>
                            </body>
                        </body>
                    </body>
                </body>
            </body>
        </body>
    </worldbody>
    <actuator>
        <position joint="joint_1"/>
        <position joint="joint_2"/>
        <position joint="joint_3"/>
        <position joint="joint_4"/>
        <position joint="joint_5"/>
        <position joint="joint_6"/>
        <!-- Define actuators for any additional joints if necessary -->
    </actuator>
</mujoco>
