<mujoco model="niryo_one">
  <compiler angle="radian"/>
  <option timestep="0.005" gravity="0 0 -9.8" noslip_iterations="5" solver="Newton"/>
  <asset>
    <mesh name="base_link" file="base_link.stl"/>
    <mesh name="shoulder_link" file="shoulder_link.stl"/>
    <mesh name="arm_link" file="arm_link.stl"/>
    <mesh name="elbow_link" file="elbow_link.stl"/>
    <mesh name="forearm_link" file="forearm_link.stl"/>
    <mesh name="wrist_link" file="wrist_link.stl"/>
    <mesh name="hand_link" file="hand_link.stl"/>
    <mesh name="g1_mainSupport" file="g1_mainSupport.stl"/>
    <mesh name="g1_clampLeft" file="g1_clampLeft.stl"/>
    <mesh name="g1_clampRight" file="g1_clampRight.stl"/>
    <texture name="chess_texture" file="chess_board.png" type="2d"/>
    <material name="chess_material" texture="chess_texture" texuniform="true" texrepeat="8 12"/>
    <texture name="A_label" file="A.png" type="2d"/>
    <material name="A_label_material" texture="A_label" texuniform="true" texrepeat="100 100"/>
    <texture name="B_label" file="B.png" type="2d"/>
    <material name="B_label_material" texture="B_label" texuniform="true" texrepeat="100 100"/>
    <texture name="C_label" file="C.png" type="2d"/>
    <material name="C_label_material" texture="C_label" texuniform="true" texrepeat="100 100"/>
    <texture name="1_label" file="1.png" type="2d"/>
    <material name="1_label_material" texture="1_label" texuniform="true" texrepeat="100 100"/>
    <texture name="2_label" file="2.png" type="2d"/>
    <material name="2_label_material" texture="2_label" texuniform="true" texrepeat="100 100"/>
    <texture name="3_label" file="3.png" type="2d"/>
    <material name="3_label_material" texture="3_label" texuniform="true" texrepeat="100 100"/>
    <texture name="4_label" file="4.png" type="2d"/>
    <material name="4_label_material" texture="4_label" texuniform="true" texrepeat="100 100"/>
    <texture name="5_label" file="5.png" type="2d"/>
    <material name="5_label_material" texture="5_label" texuniform="true" texrepeat="100 100"/>
    <texture name="6_label" file="6.png" type="2d"/>
    <material name="6_label_material" texture="6_label" texuniform="true" texrepeat="100 100"/>
    <texture name="7_label" file="7.png" type="2d"/>
    <material name="7_label_material" texture="7_label" texuniform="true" texrepeat="100 100"/>
    <texture name="8_label" file="8.png" type="2d"/>
    <material name="8_label_material" texture="8_label" texuniform="true" texrepeat="100 100"/>
  </asset>
  <worldbody>
    <body name="table" pos="0 0 0">
        <geom name="table_top" type="box" size="0.5 0.5 0.05" pos="0 0 0.05" rgba="0.8 0.8 0.8 1" friction="0.8 0.8 0.8"/>
        <!-- Specific area for the chessboard texture -->
        <geom name="chess_area" type="box" size="0.2 0.3 0.001" pos="0.26 0 0.1" material="chess_material"/>
        <!-- Label A -->
        <geom name="A_label" type="box" size="0.01 0.01 0.002" pos="0.195 -0.19 0.1" material="A_label_material"/>
        <!-- Label B -->
        <geom name="B_label" type="box" size="0.01 0.01 0.002" pos="0.235 -0.19 0.1" material="B_label_material"/>
        <!-- Label C -->
        <geom name="C_label" type="box" size="0.01 0.01 0.002" pos="0.28 -0.19 0.1" material="C_label_material"/>
        <!-- Label 1 -->
        <geom name="1_label" type="box" size="0.01 0.01 0.002" pos="0.32 -0.145 0.1" material="1_label_material"/>
        <!-- Label 2 -->
        <geom name="2_label" type="box" size="0.01 0.01 0.002" pos="0.32 -0.105 0.1" material="2_label_material"/>
        <!-- Label 3 -->
        <geom name="3_label" type="box" size="0.01 0.01 0.002" pos="0.32 -0.065 0.1" material="3_label_material"/>
        <!-- Label 4 -->
        <geom name="4_label" type="box" size="0.01 0.01 0.002" pos="0.32 -0.025 0.1" material="4_label_material"/>
        <!-- Label 5 -->
        <geom name="5_label" type="box" size="0.01 0.01 0.002" pos="0.32 0.02 0.1" material="5_label_material"/>
        <!-- Label 6 -->
        <geom name="6_label" type="box" size="0.01 0.01 0.002" pos="0.32 0.06 0.1" material="6_label_material"/>
        <!-- Label 7 -->
        <geom name="7_label" type="box" size="0.01 0.01 0.002" pos="0.32 0.10 0.1" material="7_label_material"/>
        <!-- Label 8 -->
        <geom name="8_label" type="box" size="0.01 0.01 0.002" pos="0.32 0.145 0.1" material="8_label_material"/>
    </body>
    <geom pos="0 0 0.1" type="mesh" mesh="base_link"/>
    <light name="overhead_light" dir="0 0 -1" diffuse="1 1 1" specular="0.5 0.5 0.5" pos="0 0 2"/>
    <body name="shoulder_link" pos="0 0 0.203">
      <inertial pos="0 0 0" mass="0.71142" diaginertia="0.0017 0.0017 0.0032"/>
      <joint name="joint_1" axis="0 0 1" range="-2.949 2.949" actuatorfrcrange="-2 2"/>
      <geom type="mesh" mesh="shoulder_link"/>
      <body name="arm_link" pos="0 0 0.08" quat="0.5 0.5 -0.5 0.5">
        <inertial pos="0 0 0" mass="1.0838" diaginertia="0.008194 0.0011945 0.007915"/>
        <joint name="joint_2" pos="0 0 0" axis="0 0 1" range="-1.83 0.61" actuatorfrcrange="-3 3"/>
        <geom type="mesh" mesh="arm_link"/>
        <body name="elbow_link" pos="0.21 0 0" quat="0.707107 0 0 -0.707107">
          <inertial pos="0 0 0" mass="0.22126" diaginertia="0.0011754 0.0020851 0.0022753"/>
          <joint name="joint_3" pos="0 0 0" axis="0 0 1" range="-1.34 1.57" actuatorfrcrange="-3 3"/>
          <geom type="mesh" mesh="elbow_link"/>
          <body name="forearm_link" pos="0.0415 0.03 0" quat="0.707107 0 0.707107 0">
            <inertial pos="0 0 0" mass="0.35686" diaginertia="0.0013664 0.0014781 0.00023715"/>
            <joint name="joint_4" pos="0 0 0" axis="0 0 1" range="-2.089 2.089" actuatorfrcrange="-2 2"/>
            <geom type="mesh" mesh="forearm_link"/>
            <body name="wrist_link" pos="0 0 0.19" quat="0.707107 0 -0.707107 0">
              <inertial pos="0 0 0" mass="0.22126" diaginertia="0.0015 0.0015 0.0015"/>
              <joint name="joint_5" pos="0 0 0" axis="0 0 1" range="-1.04533 0.2397" actuatorfrcrange="-2 2"/>
              <geom type="mesh" mesh="wrist_link"/>
              <body name="hand_link" pos="0.0164 -0.0055 0" quat="0.707107 0 0.707107 0">
                <inertial pos="0 0 0" mass="0.0070027" diaginertia="0.0015 0.0015 0.0015"/>
                <joint name="joint_6" pos="0 0 0" axis="0 0 1" range="-1.57436 1.57436" actuatorfrcrange="-1 1"/>
                <geom type="mesh" mesh="hand_link"/>
                <body name="g1_mainSupport_link" pos="0 0 0.0203" quat="0 1 0 0">
                  <geom type="mesh" mesh="g1_mainSupport"/>
                  <inertial pos="0 0 0" mass="0.04" diaginertia="0.000039 0.000039 0.000067"/>
                  <body name="gripper_clamp_left" pos="0 0 0" quat="0 0 0 1">
                    <joint name="left_clamp_joint" pos="0 0 0" axis="1 0 0" type="slide" range="-0.012 0" actuatorfrcrange="-0.1 0.1"/>
                    <geom type="mesh" mesh="g1_clampLeft" name="g1_clampLeft" group="0" solref="0.01 0.5" friction = "2 0.05 0.0001" conaffinity="1" contype="1"/>
                  </body>
                  <body name="gripper_clamp_right" pos="0 0 0" quat="0 0 0 1">
                    <joint name="right_clamp_joint" pos="0 0 0" axis="1 0 0" type="slide" range="0 0.012" actuatorfrcrange="-0.1 0.1"/>
                    <geom type="mesh" mesh="g1_clampRight" name="g1_clampRight" group="0" solref="0.01 0.5" friction = "2 0.05 0.0001" conaffinity="1" contype="1"/>
                  </body>
                  <site name="gripper_center" pos="0 0 -0.0453" size="0.001" rgba="0 0 0 0"/>
                </body>
              </body>
            </body>
          </body>
        </body>
      </body>
    </body>
    <!-- <body name="ball_A3" mocap="true" pos="0.195 -0.065 0.107">
        <inertial pos="0 0 0" mass="0.1" diaginertia="0.0001 0.0001 0.0001"/>
        <geom name="boxA3" type="sphere" size="0.010" rgba="0.65 0.81 0.55 1"
              friction="1 0.005 0.0001" contype="1" conaffinity="1"/>
    </body> -->
    <body name="ball_B5" mocap="true" pos="0.235 0.02 0.107">
        <inertial pos="0 0 0" mass="0.1" diaginertia="0.0001 0.0001 0.0001"/>
        <geom name="boxE6" type="sphere" size="0.010" rgba="0.65 0.81 0.55 1"
              friction="1 0.005 0.0001" contype="1" conaffinity="1"/>
    </body>
    <body name="ball_C3" mocap="true" pos="0.275 -0.065 0.107">
        <inertial pos="0 0 0" mass="0.1" diaginertia="0.0001 0.0001 0.0001"/>
        <geom name="boxH7" type="sphere" size="0.010" rgba="0.65 0.55 0.81 1"
              friction="1 0.005 0.0001" contype="1" conaffinity="1"/>
    </body>
  </worldbody>
  <actuator>
    <position joint="joint_1"/>
    <position joint="joint_2"/>
    <position joint="joint_3"/>
    <position joint="joint_4"/>
    <position joint="joint_5"/>
    <position joint="joint_6"/>
    <position joint="left_clamp_joint"/>
    <position joint="right_clamp_joint"/>
    <!-- <motor gear="100" name="box1gear" joint="box1joint"/> -->
  </actuator>
  <sensor>
    <touch name="touch" site="gripper_center"/>
  </sensor>
</mujoco>
